[2024-04-21T11:38:01.273+0000] {taskinstance.py:1979} INFO - Dependencies all met for dep_context=non-requeueable deps ti=<TaskInstance: etl.create_tables manual__2024-04-21T11:37:58.305047+00:00 [queued]>
[2024-04-21T11:38:01.288+0000] {taskinstance.py:1979} INFO - Dependencies all met for dep_context=requeueable deps ti=<TaskInstance: etl.create_tables manual__2024-04-21T11:37:58.305047+00:00 [queued]>
[2024-04-21T11:38:01.288+0000] {taskinstance.py:2193} INFO - Starting attempt 1 of 1
[2024-04-21T11:38:01.308+0000] {taskinstance.py:2217} INFO - Executing <Task(PythonOperator): create_tables> on 2024-04-21 11:37:58.305047+00:00
[2024-04-21T11:38:01.316+0000] {standard_task_runner.py:60} INFO - Started process 91152 to run task
[2024-04-21T11:38:01.323+0000] {standard_task_runner.py:87} INFO - Running: ['***', 'tasks', 'run', 'etl', 'create_tables', 'manual__2024-04-21T11:37:58.305047+00:00', '--job-id', '131', '--raw', '--subdir', 'DAGS_FOLDER/etl.py', '--cfg-path', '/tmp/tmpw8w33g40']
[2024-04-21T11:38:01.325+0000] {standard_task_runner.py:88} INFO - Job 131: Subtask create_tables
[2024-04-21T11:38:01.383+0000] {task_command.py:423} INFO - Running <TaskInstance: etl.create_tables manual__2024-04-21T11:37:58.305047+00:00 [running]> on host e2cec6840fb2
[2024-04-21T11:38:01.496+0000] {taskinstance.py:2513} INFO - Exporting env vars: AIRFLOW_CTX_DAG_OWNER='***' AIRFLOW_CTX_DAG_ID='etl' AIRFLOW_CTX_TASK_ID='create_tables' AIRFLOW_CTX_EXECUTION_DATE='2024-04-21T11:37:58.305047+00:00' AIRFLOW_CTX_TRY_NUMBER='1' AIRFLOW_CTX_DAG_RUN_ID='manual__2024-04-21T11:37:58.305047+00:00'
[2024-04-21T11:38:01.498+0000] {taskinstance.py:2731} ERROR - Task failed with exception
Traceback (most recent call last):
  File "/home/airflow/.local/lib/python3.8/site-packages/airflow/models/taskinstance.py", line 444, in _execute_task
    result = _execute_callable(context=context, **execute_callable_kwargs)
  File "/home/airflow/.local/lib/python3.8/site-packages/airflow/models/taskinstance.py", line 414, in _execute_callable
    return execute_callable(context=context, **execute_callable_kwargs)
  File "/home/airflow/.local/lib/python3.8/site-packages/airflow/operators/python.py", line 200, in execute
    return_value = self.execute_callable()
  File "/home/airflow/.local/lib/python3.8/site-packages/airflow/operators/python.py", line 217, in execute_callable
    return self.python_callable(*self.op_args, **self.op_kwargs)
  File "/opt/airflow/dags/etl.py", line 69, in _create_tables
    table_drop_events,
NameError: name 'table_drop_events' is not defined
[2024-04-21T11:38:01.507+0000] {taskinstance.py:1149} INFO - Marking task as FAILED. dag_id=etl, task_id=create_tables, execution_date=20240421T113758, start_date=20240421T113801, end_date=20240421T113801
[2024-04-21T11:38:01.534+0000] {standard_task_runner.py:107} ERROR - Failed to execute job 131 for task create_tables (name 'table_drop_events' is not defined; 91152)
[2024-04-21T11:38:01.576+0000] {local_task_job_runner.py:234} INFO - Task exited with return code 1
[2024-04-21T11:38:01.618+0000] {taskinstance.py:3312} INFO - 0 downstream tasks scheduled from follow-on schedule check
